Workbook
Name ConceptList: 'START_HERE'!$K$1:$K$27
Name PlayWatchList: 'START_HERE'!$L$1:$L$71
Name SituationList: 'START_HERE'!$J$1:$J$18

Sheet START_HERE
A1: WEEKLY GAMEPLAN • START HERE | J1: All situations | K1: 3 STEP | L1: 2 BUBBLE SCREEN
A2: START | C2: FIND A CALL | F2: OPPONENT ALERTS | J2: P&10 | K2: 5 STEP | L2: 3 ARROW SCREEN
A3: Opponent tendencies + defensive concept call-fit signals. Film review confirms the numbers. | J3: 1D 1-3 | K3: BELLY | L3: CLIMB POST WHEEL
J4: 1D 4-6 | K4: BOOT | L4: CURL OVER VERT
A5: Set the week, then use FIND A CALL. The coach-facing boards are the product. | J5: 1D 7-10 | K5: COUNTER | L5: CURL OVER Y WAGGLE
A6: Week / opponent | B6: CURRENT IMPORTED SAMPLE | J6: 1D 11+ | K6: DASH | L6: DART STG READ
J7: 2D 1-3 | K7: DRAW | L7: DIG HITCH TB SWING
A8: FIND A CALL | B8: Choose concept, situation or exact-play watch. Candidates and cautions appear at the top. | J8: 2D 4-6 | K8: DUO | L8: DIG SEAM OVER
J9: 2D 7-10 | K9: FLY SWEEP | L9: DIG SEAM SMASH
A10: OPPONENT RESPONSE CARD | B10: Read D&D alerts alongside matching defensive context or concept evidence. | J10: 2D 11+ | K10: FLY TOSS | L10: DIG SEAM UNDER
J11: 3D 1-3 | K11: FUZZY | L11: DOUBLE SPOT ARROW
A12: PRINT GAMEPLAN SUMMARY | B12: Two-page coach summary with identity, call-fit signals and film/practice watches. | J12: 3D 4-6 | K12: G | L12: FLOOD
J13: 3D 7-10 | K13: INSIDE ZONE | L13: FLY MOTION PASS
A14: BUILD PRACTICE PRIORITIES | B14: Rep strengths, review problem calls, and track opponent exact plays. | J14: 3D 11+ | K14: MAN | L14: FLY POWE READ STG
J15: 4D 1-3 | K15: OPTION | L15: FLY POWER READ STG
A16: CHECK WORKBOOK HEALTH | B16: Review PASS / REVIEW statuses before building the call sheet. | J16: 4D 4-6 | K16: OUTSIDE ZONE | L16: G STG LEAD
J17: 4D 7-10 | K17: PAP | L17: G STG READ
J18: 4D 11+ | K18: PIN PULL | L18: G WK LEAD
A19: WHAT THE TWO SCOUTS TELL US | K19: POWER | L19: H FLY SWEEP STG
A20: Opponent Breakdown identifies what they tend to do: concepts, personnel, structures and actual playcalls. | K20: POWER READ | L20: H FLY SWEEP STG OPTION
A21: Defensive Self Scout identifies what our calls have done well or poorly in tagged concepts and situations. | K21: RPO | L21: H FLY TOSS
A22: This workbook identifies call-fit candidates, risk areas and practice priorities. It guides the football conversation; it does not automatically call defenses. | K22: SCREEN | L22: HITCH OVER
A23: Film review confirms the numbers. Match fit, execution and the actual offensive presentation before changing call usage. | K23: SOP | L23: HITCH POST OVER
K24: SPLIT ZONE | L24: LEVELS UNDER
A25: EXACT PLAYS: HONEST EVIDENCE RULE | K25: TOSS PASS | L25: LOAD OPTION STG
A26: Opponent Exact-Play Watch = opponent evidence. Concept Proxy = defensive results for a confirmed concept. No Defensive Exact-Play Sample is supplied. A proxy is never direct proof against the named play. | K26: TRAP | L26: MESH TB WHEEL
A27: Six opponent play names map to more than one concept. Those proxy fields stay blank until a coach confirms the concept. Do not infer the answer from the play name. | K27: WHAM | L27: OPTION ROUTES
A28: MATCHING SCOPE shows which tags match. Exact Context Match means the tagged D&D / presentation / concept world, never an exact offensive play. Sample Watch marks limited reps. | L28: OZ STG LEAD
A29: CALL-FIT AND WATCH RULES | L29: OZ STG LEAD READ
A30: Success-rate watch | B30: 0.5 | C30: Below this rate is a watch item; not a rewritten scoring rule. | L30: OZ STG READ
A31: Explosive-rate watch | B31: 0.2 | C31: At or above this rate is an Explosive Alert. | L31: OZ STG SPLIT READ
A32: Average-gain watch | B32: 7 | C32: Above this average is a gain-control watch item. | L32: OZ TOSS STG
A33: Call-fit score watch | B33: 50 | C33: Below this score is a call-sheet / practice review signal. | L33: OZ WK LEAD READ
A34: Score = ROUND(success rate × 70 + explosive prevention × 20 + clamped gain control × 10, 1). Confidence: 1–2 TRACK; 3 LOW; 4–6 MEDIUM; 7+ HIGH. | L34: OZ WK READ
A35: Ranking first separates calls meeting the lookup minimum (default 4 reps). Among that group, non-problem / non-explosive candidates lead, then score and reps. If no call meets the minimum, show the best-supported small sample with its caution. | L35: POST DIG UNDER
L36: POST OVER WHEEL
A37: WEEKLY WORKFLOW | L37: POST WHEEL SWING
A38: 1. Finish and check both source scouts. Send the two updated workbooks to refresh this married gameplan for a new week. | L38: POWER READ STG
A39: 2. Save this week’s gameplan copy. This file is a self-contained snapshot of the supplied scouts, not a live external import. | L39: QB G STG LEAD
A40: 3. Use CALL_LOOKUP_BOARD. Set the situation, concept, exact-play watch and minimum reps. Review confidence and cautions before taking a candidate to the call sheet. | L40: QB G WK LEAD
...

Sheet OPPONENT_IMPORT
A1: OPPONENT SOURCE IMPORT
A2: START | C2: FIND A CALL | F2: OPPONENT ALERTS | I2: PRACTICE
A3: These are standalone value snapshots. Coach answers are on the lookup, response card, cheat sheet and practice board. Refresh from completed source scouts each week.
A7: Required source section | B7: Imported rows | C7: Import mode | D7: Navigation
A8: MASTER_STRATEGY_CARD | B8: 38 | C8: Imported values | D8: View source output
A9: MASTER_SIGNAL_BOARD | B9: 694 | C9: Imported values | D9: View source output
A10: MASTER_SNAPSHOT | B10: 73 | C10: Imported values | D10: View source output
A11: MASTER_IDENTITY_BOARD | B11: 81 | C11: Imported values | D11: View source output
A12: MASTER_DD_CONCEPT_IDENTITY | B12: 82 | C12: Imported values | D12: View source output
A13: MASTER_DD_PLAYCALL_IDENTITY | B13: 130 | C13: Imported values | D13: View source output
A14: MASTER_DD_PERSONNEL_CONCEPT | B14: 100 | C14: Imported values | D14: View source output
A15: MASTER_DD_STRUCTURE_CONCEPT | B15: 112 | C15: Imported values | D15: View source output
A16: MASTER_DD_PER_PLAYCALL | B16: 142 | C16: Imported values | D16: View source output
A17: MASTER_DD_STRUCTURE_PLAYCALL | B17: 142 | C17: Imported values | D17: View source output
A18: MASTER_INPUT | B18: 176 | C18: Imported values | D18: View source output
A19: FORMULA_CHECK | B19: 50 | C19: Imported values | D19: View source output
A39: NORMALIZED PLAY EVIDENCE
A40: Source scoring flags are copied as values. Missing tags and exclusions retain their original meaning; no football scoring rules are rewritten.
A41: Source Row | B41: Down | C41: D&D Bucket | D41: Personnel | E41: Structure | F41: Concept | G41: Actual Playcall | H41: Result | I41: Gain / Loss | J41: Source Eligible | K41: Offensive Success | L41: Explosive | M41: Play Type
A43: 3 | B43: P | C43: P&10 | D43: 11 | E43: 3X1 | I43: 0 | J43: 0
A44: 4 | B44: P | C44: P&10 | D44: 21H | E44: 2X1 | F44: 5 STEP | G44: HITCH OVER | H44: COMPLETE | I44: 5 | J44: 1 | K44: 0 | L44: 0 | M44: PASS
A45: 5 | B45: P | C45: P&10 | D45: 12 | E45: 2X2 | F45: OUTSIDE ZONE | G45: OZ STG SPLIT READ | H45: RUSH | I45: 0 | J45: 1 | K45: 0 | L45: 0 | M45: RUSH
A46: 6 | B46: P | C46: P&10 | D46: 11 | E46: 2X2 | F46: 5 STEP | G46: HITCH POST OVER | H46: QB SCRAMBLE | I46: 9 | J46: 1 | K46: 1 | L46: 0 | M46: SCRAMBLE
A47: 7 | B47: P | C47: P&10 | D47: 11 | E47: 2X2 | F47: OUTSIDE ZONE | G47: OZ STG READ | H47: RUSH | I47: 10 | J47: 1 | K47: 1 | L47: 0 | M47: RUSH
A48: 8 | B48: P | C48: P&10 | D48: 11 | E48: 2X2 | F48: RPO | G48: 2 BUBBLE SCREEN | H48: COMPLETE | I48: 5 | J48: 1 | K48: 0 | L48: 0 | M48: PASS
A49: 9 | B49: P | C49: P&10 | D49: 11 | E49: 2X2 | F49: PAP | G49: FLOOD | H49: COMPLETE | I49: 0 | J49: 1 | K49: 0 | L49: 0 | M49: PASS
A50: 10 | B50: P | C50: P&10 | D50: 11 | E50: 2X2 | F50: FLY SWEEP | G50: H FLY SWEEP STG | H50: RUSH | I50: -2 | J50: 1 | K50: 0 | L50: 0 | M50: RUSH
A51: 11 | B51: P | C51: P&10 | D51: 11 | E51: 2X2 | F51: POWER | G51: DART STG READ | H51: RUSH | I51: 6 | J51: 1 | K51: 1 | L51: 0 | M51: RUSH
A52: 12 | B52: P | C52: P&10 | D52: 11 | E52: 3X1 | F52: 5 STEP | G52: OPTION ROUTES | H52: QB SCRAMBLE | I52: 0 | J52: 1 | K52: 0 | L52: 0 | M52: SCRAMBLE
A53: 13 | B53: P | C53: P&10 | D53: 11 | E53: 3X1 | F53: SCREEN | G53: TB SWING SCREEN | H53: BATTED PASS | I53: 0 | J53: 1 | K53: 0 | L53: 0 | M53: PASS
A54: 14 | B54: P | C54: P&10 | D54: 11 | E54: 3X1 | F54: INSIDE ZONE | G54: ZONE STG INSERT READ | H54: RUSH | I54: 3 | J54: 1 | K54: 1 | L54: 0 | M54: RUSH
A55: 15 | B55: P | C55: P&10 | D55: 11 | E55: 2X2 | F55: OPTION | G55: ZONE WK READ OPTION | H55: RUSH | I55: 0 | J55: 1 | K55: 0 | L55: 0 | M55: RUSH
... A79: 39 | B79: P | C79: P&10 | D79: 12 | E79: 3X1 | F79: INSIDE ZONE | G79: ZONE STG SPLIT READ | H79: RUSH | I79: 12 | J79: 1 | K79: 1 | L79: 1 | M79: RUSH
A80: 40 | B80: P | C80: P&10 | D80: 12 | E80: 1X1 | I80: -2 | J80: 0
A81: 41 | B81: 1 | C81: 4-6 | D81: 11 | E81: 2X2 | F81: OUTSIDE ZONE | G81: OZ STG READ | H81: RUSH | I81: -2 | J81: 1 | K81: 0 | L81: 0 | M81: RUSH
A82: 42 | B82: 1 | C82: 7-10 | D82: 11 | E82: 3X2 | F82: SCREEN | G82: TB SWING SCREEN | H82: QB SCRAMBLE | I82: 0 | J82: 1 | K82: 0 | L82: 0 | M82: SCRAMBLE
A83: 43 | B83: 1 | C83: 7-10 | D83: 12 | E83: 2X2 | F83: INSIDE ZONE | G83: ZONE WK READ | H83: RUSH | I83: 0 | J83: 1 | K83: 0 | L83: 0 | M83: RUSH
A84: 44 | B84: 1 | C84: 7-10 | D84: 11 | E84: 3X1 | F84: OUTSIDE ZONE | G84: OZ STG READ | H84: RUSH | I84: 8 | J84: 1 | K84: 1 | L84: 0 | M84: RUSH
A85: 45 | B85: 1 | C85: 7-10 | D85: 11 | E85: 2X2 | F85: FLY SWEEP | G85: H FLY SWEEP STG | H85: RUSH | I85: 9 | J85: 1 | K85: 1 | L85: 0 | M85: RUSH
A86: 46 | B86: 1 | C86: 7-10 | D86: 11 | E86: 3X1 | F86: SOP | G86: SPOT SMASH ARROW | H86: COMPLETE | I86: 1 | J86: 1 | K86: 0 | L86: 0 | M86: PASS
...

Sheet DEF_SELF_SCOUT_IMPORT
A1: DEFENSIVE SELF-SCOUT SOURCE IMPORT
A2: START | C2: FIND A CALL | F2: OPPONENT ALERTS | I2: PRACTICE
A3: These are standalone value snapshots. Coach answers are on the lookup, response card, cheat sheet and practice board. Refresh from completed source scouts each week.
A7: Required source section | B7: Imported rows | C7: Import mode | D7: Navigation
A8: DEF_INPUT | B8: 288 | C8: Imported values | D8: View source output
A9: DEF_SNAPSHOT | B9: 52 | C9: Imported values | D9: View source output
A10: DEF_ALL | B10: 63 | C10: Imported values | D10: View source output
A11: DEF_D&D | B11: 172 | C11: Imported values | D11: View source output
A12: DEF_CONCEPT | B12: 248 | C12: Imported values | D12: View source output
A13: DEF_11P_ALL | B13: 57 | C13: Imported values | D13: View source output
A14: DEF_11P_3X1 | B14: 47 | C14: Imported values | D14: View source output
A15: DEF_11P_2X2 | B15: 39 | C15: Imported values | D15: View source output
A16: DEF_12P_3X1 | B16: 10 | C16: Imported values | D16: View source output
A17: DEF_12P_2X2 | B17: 15 | C17: Imported values | D17: View source output
A18: DEF_00P_3X1 | B18: 11 | C18: Imported values | D18: View source output
A19: DEF_OTHER | B19: 23 | C19: Imported values | D19: View source output
... A32: DEF_FORMULA_CHECK | B32: 120 | C32: Imported values | D32: View source output
A39: NORMALIZED PLAY EVIDENCE
A40: Source scoring flags are copied as values. Missing tags and exclusions retain their original meaning; no football scoring rules are rewritten.
A41: Source Row | B41: Down | C41: D&D Bucket | D41: Concept | E41: Hot Call | F41: Personnel | G41: Structure Family | H41: Play Type | I41: Gain / Loss | J41: Defensive Success | K41: Explosive Allowed | L41: Clean Play | M41: Original Result | N41: Original Structure | O41: PS Bucket | P41: Source Caution | Q41: Situation | R41: Coverage
A42: 2 | B42: P | C42: P&10 | D42: DRAW | E42: BOURBON | F42: 11 | G42: 2X2 | H42: RUSH | I42: 14 | J42: 0 | K42: 1 | L42: Y | M42: RUSH | N42: 2x2 | O42: 11P_2X2 | Q42: =IF(B42="","",IF(B42="P","P&10",B42&"D "&C42)) -> P&10 | R42: =IF(L42<>"Y","",IF(COUNTIF('DEF_CALL_DECISION_SUPPORT'!$B$1197:$B$1256,SUBSTITUTE(SUBSTITUTE(SUBSTITUTE(E42,"~","~~"),"*","~*"),"?","~?"))>0,"KNOWN","REVIEW: new call; refresh sources")) -> KNOWN
A43: 3 | B43: P | C43: P&10 | D43: INSIDE ZONE | E43: BOURBON | F43: 11 | G43: 2X2 | H43: RUSH | I43: 4 | J43: 0 | K43: 0 | L43: Y | M43: RUSH | N43: 2x2 | O43: 11P_2X2 | Q43: =IF(B43="","",IF(B43="P","P&10",B43&"D "&C43)) -> P&10 | R43: =IF(L43<>"Y","",IF(COUNTIF('DEF_CALL_DECISION_SUPPORT'!$B$1197:$B$1256,SUBSTITUTE(SUBSTITUTE(SUBSTITUTE(E43,"~","~~"),"*","~*"),"?","~?"))>0,"KNOWN","REVIEW: new call; refresh sources")) -> KNOWN
A44: 4 | B44: P | C44: P&10 | D44: INSIDE ZONE | E44: BOURBON | F44: 11 | G44: 2X2 | H44: RUSH | I44: 7 | J44: 0 | K44: 0 | L44: Y | M44: RUSH | N44: 2x2 | O44: 11P_2X2 | Q44: =IF(B44="","",IF(B44="P","P&10",B44&"D "&C44)) -> P&10 | R44: =IF(L44<>"Y","",IF(COUNTIF('DEF_CALL_DECISION_SUPPORT'!$B$1197:$B$1256,SUBSTITUTE(SUBSTITUTE(SUBSTITUTE(E44,"~","~~"),"*","~*"),"?","~?"))>0,"KNOWN","REVIEW: new call; refresh sources")) -> KNOWN
A45: 5 | B45: P | C45: P&10 | D45: PAP | E45: BOURBON | F45: 00 | G45: 2X2 | H45: DROPBACK | I45: 47 | J45: 0 | K45: 1 | L45: Y | M45: COMPLETE | N45: 2x2 | O45: OTHER | Q45: =IF(B45="","",IF(B45="P","P&10",B45&"D "&C45)) -> P&10 | R45: =IF(L45<>"Y","",IF(COUNTIF('DEF_CALL_DECISION_SUPPORT'!$B$1197:$B$1256,SUBSTITUTE(SUBSTITUTE(SUBSTITUTE(E45,"~","~~"),"*","~*"),"?","~?"))>0,"KNOWN","REVIEW: new call; refresh sources")) -> KNOWN
A46: 6 | B46: P | C46: P&10 | D46: COUNTER | E46: BOURBON | F46: 00 | G46: 3X1 | H46: RUSH | I46: 4 | J46: 0 | K46: 0 | L46: Y | M46: RUSH | N46: 3x1 | O46: 00P_3X1 | Q46: =IF(B46="","",IF(B46="P","P&10",B46&"D "&C46)) -> P&10 | R46: =IF(L46<>"Y","",IF(COUNTIF('DEF_CALL_DECISION_SUPPORT'!$B$1197:$B$1256,SUBSTITUTE(SUBSTITUTE(SUBSTITUTE(E46,"~","~~"),"*","~*"),"?","~?"))>0,"KNOWN","REVIEW: new call; refresh sources")) -> KNOWN
A47: 7 | B47: P | C47: P&10 | D47: INSIDE ZONE | E47: BOURBON | F47: 00 | G47: 2X2 | H47: RUSH | I47: 6 | J47: 0 | K47: 0 | L47: Y | M47: RUSH | N47: 2x2 | O47: OTHER | Q47: =IF(B47="","",IF(B47="P","P&10",B47&"D "&C47)) -> P&10 | R47: =IF(L47<>"Y","",IF(COUNTIF('DEF_CALL_DECISION_SUPPORT'!$B$1197:$B$1256,SUBSTITUTE(SUBSTITUTE(SUBSTITUTE(E47,"~","~~"),"*","~*"),"?","~?"))>0,"KNOWN","REVIEW: new call; refresh sources")) -> KNOWN
A48: 8 | B48: P | C48: P&10 | D48: INSIDE ZONE | E48: KEY CAPTAIN | F48: 12 | G48: 3X1 | H48: RUSH | I48: 5 | J48: 0 | K48: 0 | L48: Y | M48: RUSH | N48: 1x3 | O48: 12P_3X1 | Q48: =IF(B48="","",IF(B48="P","P&10",B48&"D "&C48)) -> P&10 | R48: =IF(L48<>"Y","",IF(COUNTIF('DEF_CALL_DECISION_SUPPORT'!$B$1197:$B$1256,SUBSTITUTE(SUBSTITUTE(SUBSTITUTE(E48,"~","~~"),"*","~*"),"?","~?"))>0,"KNOWN","REVIEW: new call; refresh sources")) -> KNOWN
A49: 9 | B49: P | C49: P&10 | D49: PAP | E49: KEY CAPTAIN | F49: 12 | G49: 3X1 | H49: DROPBACK | I49: -7 | J49: 1 | K49: 0 | L49: Y | M49: SACK | N49: 3x1 | O49: 12P_3X1 | Q49: =IF(B49="","",IF(B49="P","P&10",B49&"D "&C49)) -> P&10 | R49: =IF(L49<>"Y","",IF(COUNTIF('DEF_CALL_DECISION_SUPPORT'!$B$1197:$B$1256,SUBSTITUTE(SUBSTITUTE(SUBSTITUTE(E49,"~","~~"),"*","~*"),"?","~?"))>0,"KNOWN","REVIEW: new call; refresh sources")) -> KNOWN
A50: 10 | B50: P | C50: P&10 | D50: INSIDE ZONE | E50: KEY CAPTAIN | F50: 12 | G50: 2X2 | H50: RUSH | I50: 6 | J50: 0 | K50: 0 | L50: Y | M50: RUSH | N50: 2x2 | O50: 12P_2X2 | Q50: =IF(B50="","",IF(B50="P","P&10",B50&"D "&C50)) -> P&10 | R50: =IF(L50<>"Y","",IF(COUNTIF('DEF_CALL_DECISION_SUPPORT'!$B$1197:$B$1256,SUBSTITUTE(SUBSTITUTE(SUBSTITUTE(E50,"~","~~"),"*","~*"),"?","~?"))>0,"KNOWN","REVIEW: new call; refresh sources")) -> KNOWN
A51: 11 | B51: P | C51: P&10 | D51: INSIDE ZONE | E51: KEY CAPTAIN | F51: 12 | G51: 2X2 | H51: RUSH | I51: 2 | J51: 1 | K51: 0 | L51: Y | M51: RUSH | N51: 2x2 | O51: 12P_2X2 | Q51: =IF(B51="","",IF(B51="P","P&10",B51&"D "&C51)) -> P&10 | R51: =IF(L51<>"Y","",IF(COUNTIF('DEF_CALL_DECISION_SUPPORT'!$B$1197:$B$1256,SUBSTITUTE(SUBSTITUTE(SUBSTITUTE(E51,"~","~~"),"*","~*"),"?","~?"))>0,"KNOWN","REVIEW: new call; refresh sources")) -> KNOWN
A52: 12 | B52: P | C52: P&10 | D52: RPO | E52: TEX | F52: 11 | G52: 3X1 | H52: DROPBACK | I52: 0 | J52: 1 | K52: 0 | L52: Y | M52: INCOMPLETE | N52: 3x1 | O52: 11P_3X1 | Q52: =IF(B52="","",IF(B52="P","P&10",B52&"D "&C52)) -> P&10 | R52: =IF(L52<>"Y","",IF(COUNTIF('DEF_CALL_DECISION_SUPPORT'!$B$1197:$B$1256,SUBSTITUTE(SUBSTITUTE(SUBSTITUTE(E52,"~","~~"),"*","~*"),"?","~?"))>0,"KNOWN","REVIEW: new call; refresh sources")) -> KNOWN
A53: 13 | B53: P | C53: P&10 | D53: BOOT | E53: TEX | F53: 11 | G53: 3X1 | H53: DROPBACK | I53: -10 | J53: 1 | K53: 0 | L53: Y | M53: SACK | N53: 1x3 | O53: 11P_3X1 | Q53: =IF(B53="","",IF(B53="P","P&10",B53&"D "&C53)) -> P&10 | R53: =IF(L53<>"Y","",IF(COUNTIF('DEF_CALL_DECISION_SUPPORT'!$B$1197:$B$1256,SUBSTITUTE(SUBSTITUTE(SUBSTITUTE(E53,"~","~~"),"*","~*"),"?","~?"))>0,"KNOWN","REVIEW: new call; refresh sources")) -> KNOWN
... A62: 22 | B62: P | C62: P&10 | D62: RPO | E62: KEY BOURBON | F62: 12 | G62: 3X1 | H62: DROPBACK | I62: 14 | J62: 0 | K62: 0 | L62: Y | M62: COMPLETE | N62: 3x1 | O62: 12P_3X1 | Q62: =IF(B62="","",IF(B62="P","P&10",B62&"D "&C62)) -> P&10 | R62: =IF(L62<>"Y","",IF(COUNTIF('DEF_CALL_DECISION_SUPPORT'!$B$1197:$B$1256,SUBSTITUTE(SUBSTITUTE(SUBSTITUTE(E62,"~","~~"),"*","~*"),"?","~?"))>0,"KNOWN","REVIEW: new call; refresh sources")) -> KNOWN
A63: 23 | B63: P | C63: P&10 | E63: KEY BOURBON | F63: 12 | G63: 3X1 | H63: EXCLUDE | I63: 0 | L63: N | N63: 1x3 | O63: 12P_3X1 | P63: Excluded source record. | Q63: =IF(B63="","",IF(B63="P","P&10",B63&"D "&C63)) -> P&10 | R63: =IF(L63<>"Y","",IF(COUNTIF('DEF_CALL_DECISION_SUPPORT'!$B$1197:$B$1256,SUBSTITUTE(SUBSTITUTE(SUBSTITUTE(E63,"~","~~"),"*","~*"),"?","~?"))>0,"KNOWN","REVIEW: new call; refresh sources"))
A64: 24 | B64: P | C64: P&10 | D64: SPLIT ZONE | E64: MIX BOURBON | F64: 12 | G64: 2X2 | H64: RUSH | I64: 6 | J64: 0 | K64: 0 | L64: Y | M64: RUSH | N64: 2x2 | O64: 12P_2X2 | Q64: =IF(B64="","",IF(B64="P","P&10",B64&"D "&C64)) -> P&10 | R64: =IF(L64<>"Y","",IF(COUNTIF('DEF_CALL_DECISION_SUPPORT'!$B$1197:$B$1256,SUBSTITUTE(SUBSTITUTE(SUBSTITUTE(E64,"~","~~"),"*","~*"),"?","~?"))>0,"KNOWN","REVIEW: new call; refresh sources")) -> KNOWN
A65: 25 | B65: P | C65: P&10 | D65: INSIDE ZONE | E65: MIX BOURBON | F65: 11 | G65: 2X2 | H65: RUSH | I65: 17 | J65: 0 | K65: 1 | L65: Y | M65: RUSH | N65: 2x2 | O65: 11P_2X2 | Q65: =IF(B65="","",IF(B65="P","P&10",B65&"D "&C65)) -> P&10 | R65: =IF(L65<>"Y","",IF(COUNTIF('DEF_CALL_DECISION_SUPPORT'!$B$1197:$B$1256,SUBSTITUTE(SUBSTITUTE(SUBSTITUTE(E65,"~","~~"),"*","~*"),"?","~?"))>0,"KNOWN","REVIEW: new call; refresh sources")) -> KNOWN
A66: 26 | B66: P | C66: P&10 | D66: RPO | E66: OX | F66: 11 | G66: 3X1 | H66: DROPBACK | I66: 13 | J66: 0 | K66: 0 | L66: Y | M66: QB SCRAMBLE | N66: 1x3 | O66: 11P_3X1 | Q66: =IF(B66="","",IF(B66="P","P&10",B66&"D "&C66)) -> P&10 | R66: =IF(L66<>"Y","",IF(COUNTIF('DEF_CALL_DECISION_SUPPORT'!$B$1197:$B$1256,SUBSTITUTE(SUBSTITUTE(SUBSTITUTE(E66,"~","~~"),"*","~*"),"?","~?"))>0,"KNOWN","REVIEW: new call; refresh sources")) -> KNOWN
A67: 27 | B67: P | C67: P&10 | D67: INSIDE ZONE | E67: OX | F67: 11 | G67: 2X2 | H67: RUSH | I67: 4 | J67: 0 | K67: 0 | L67: Y | M67: RUSH | N67: 2x2 | O67: 11P_2X2 | Q67: =IF(B67="","",IF(B67="P","P&10",B67&"D "&C67)) -> P&10 | R67: =IF(L67<>"Y","",IF(COUNTIF('DEF_CALL_DECISION_SUPPORT'!$B$1197:$B$1256,SUBSTITUTE(SUBSTITUTE(SUBSTITUTE(E67,"~","~~"),"*","~*"),"?","~?"))>0,"KNOWN","REVIEW: new call; refresh sources")) -> KNOWN
A68: 28 | B68: P | C68: P&10 | E68: 9 DICE | H68: EXCLUDE | I68: 0 | L68: N | P68: Excluded source record. | Q68: =IF(B68="","",IF(B68="P","P&10",B68&"D "&C68)) -> P&10 | R68: =IF(L68<>"Y","",IF(COUNTIF('DEF_CALL_DECISION_SUPPORT'!$B$1197:$B$1256,SUBSTITUTE(SUBSTITUTE(SUBSTITUTE(E68,"~","~~"),"*","~*"),"?","~?"))>0,"KNOWN","REVIEW: new call; refresh sources"))
A69: 29 | B69: P | C69: P&10 | D69: 3 STEP | E69: BLIZZARD | F69: 11 | G69: 3X1 | H69: DROPBACK | I69: 3 | J69: 1 | K69: 0 | L69: Y | M69: COMPLETE | N69: 3x1 | O69: 11P_3X1 | Q69: =IF(B69="","",IF(B69="P","P&10",B69&"D "&C69)) -> P&10 | R69: =IF(L69<>"Y","",IF(COUNTIF('DEF_CALL_DECISION_SUPPORT'!$B$1197:$B$1256,SUBSTITUTE(SUBSTITUTE(SUBSTITUTE(E69,"~","~~"),"*","~*"),"?","~?"))>0,"KNOWN","REVIEW: new call; refresh sources")) -> KNOWN
...

Sheet CALL_LOOKUP_BOARD
A1: FIND A DEFENSIVE CALL-FIT CANDIDATE
A2: START | C2: FIND A CALL | F2: OPPONENT ALERTS | I2: PRACTICE
A3: Concept evidence supports defensive candidates. Exact opponent plays support watches and concept proxies; they are not proven defensive answers.
A4: CONCEPTS | C4: EXACT-PLAY WATCH | E4: D&D + CONCEPT
A5: D&D PLAY WATCH | C5: CAUTIONS | E5: SMALL SAMPLES
A6: Situation | B6: All situations | D6: Concept | E6: INSIDE ZONE
A7: Priority minimum reps | B7: 4 | D7: Exact-play watch | E7: OZ STG READ
A8: CONCEPT CALL-FIT CANDIDATE
A9: ="Concept: "&E6&" | "&B6 -> Concept: INSIDE ZONE | All situations | W9: =IF($X$9="",0,IF($B$6="All situations",IFERROR(MATCH(LEN($X$9)&":"&$X$9&"|",'DEF_CALL_DECISION_SUPPORT'!$U$1264:$U$1440,0)+1264-1,0),IFERROR(MATCH(LEN($B$6)&":"&$B$6&"|"&LEN($X$9)&":"&$X$9&"|",'DEF_CALL_DECISION_SUPPORT'!$U$811:$U$1055,0)+811-1,0))) -> 1380 | X9: =IF(Y9=0,"",IF(COUNTBLANK(INDEX($L$1:$L$730,Y9))=1,"",INDEX($L$1:$L$730,Y9))) -> OUTSIDE ZONE | Y9: =IFERROR(MATCH($E$7,$A$67:$A$137,0)+67-1,0) -> 96 | Z9: =IF($B$6="All situations",IFERROR(MATCH(LEN($E$6)&":"&$E$6&"|",'DEF_CALL_DECISION_SUPPORT'!$U$1264:$U$1440,0)+1264-1,0),IFERROR(MATCH(LEN($B$6)&":"&$B$6&"|"&LEN($E$6)&":"&$E$6&"|",'DEF_CALL_DECISION_SUPPORT'!$U$811:$U$1055,0)+811-1,0)) -> 1370
A10: ="Concept candidate: "&IF($Z$9=0,"No matching defensive reps",INDEX('DEF_CALL_DECISION_SUPPORT'!$A$1:$U$1496,$Z$9,2)) -> Concept candidate: STUD
A11: Reps | B11: =IF($Z$9=0,"",INDEX('DEF_CALL_DECISION_SUPPORT'!$A$1:$U$1496,$Z$9,3)) -> 4 | C11: Confidence | D11: =IF($Z$9=0,"",INDEX('DEF_CALL_DECISION_SUPPORT'!$A$1:$U$1496,$Z$9,9)) -> MEDIUM | E11: Call-fit score | F11: =IF($Z$9=0,"",INDEX('DEF_CALL_DECISION_SUPPORT'!$A$1:$U$1496,$Z$9,10)) -> 81
A12: Success rate | B12: =IF($Z$9=0,"",INDEX('DEF_CALL_DECISION_SUPPORT'!$A$1:$U$1496,$Z$9,4)) -> 0.75 | C12: Explosive rate | D12: =IF($Z$9=0,"",INDEX('DEF_CALL_DECISION_SUPPORT'!$A$1:$U$1496,$Z$9,5)) -> 0 | E12: Avg gain | F12: =IF($Z$9=0,"",INDEX('DEF_CALL_DECISION_SUPPORT'!$A$1:$U$1496,$Z$9,6)) -> 1.5
A13: Call label | B13: =IF($Z$9=0,"",INDEX('DEF_CALL_DECISION_SUPPORT'!$A$1:$U$1496,$Z$9,11)) -> Strong Candidate
A14: =IF($Z$9=0,"No matching defensive concept sample; film review required.",INDEX('DEF_CALL_DECISION_SUPPORT'!$A$1:$U$1496,$Z$9,12)) -> Strong call-fit candidate; confirm on film.
A15: ="MATCHING SCOPE: "&IF(Z9=0,"Film Review Required",IF(IF($Z$9=0,"",INDEX('DEF_CALL_DECISION_SUPPORT'!$A$1:$U$1496,$Z$9,3))<4,"Sample Watch • ","")&IF(B6="All situations","Broad Concept Proxy","D&D + Concept Match")) -> MATCHING SCOPE: Broad Concept Proxy
A16: OPPONENT EXACT-PLAY WATCH / CONCEPT PROXY
A17: ="Opponent Exact-Play Watch: "&E7 -> Opponent Exact-Play Watch: OZ STG READ
A18: ="Concept proxy candidate: "&IF($W$9=0,"Film Review Required",INDEX('DEF_CALL_DECISION_SUPPORT'!$A$1:$U$1496,$W$9,2)) -> Concept proxy candidate: BOURBON
A19: Concept reps | B19: =IF($W$9=0,"",INDEX('DEF_CALL_DECISION_SUPPORT'!$A$1:$U$1496,$W$9,3)) -> 3 | C19: Confidence | D19: =IF($W$9=0,"",INDEX('DEF_CALL_DECISION_SUPPORT'!$A$1:$U$1496,$W$9,9)) -> LOW | E19: Concept score | F19: =IF($W$9=0,"",INDEX('DEF_CALL_DECISION_SUPPORT'!$A$1:$U$1496,$W$9,10)) -> 48
A20: Concept success | B20: =IF($W$9=0,"",INDEX('DEF_CALL_DECISION_SUPPORT'!$A$1:$U$1496,$W$9,4)) -> 0.33333333 | C20: Concept explosive | D20: =IF($W$9=0,"",INDEX('DEF_CALL_DECISION_SUPPORT'!$A$1:$U$1496,$W$9,5)) -> 0 | E20: Concept avg gain | F20: =IF($W$9=0,"",INDEX('DEF_CALL_DECISION_SUPPORT'!$A$1:$U$1496,$W$9,6)) -> 5.3333333
A21: ="MATCHING SCOPE: No Defensive Exact-Play Sample • "&IF(W9=0,"Film Review Required",IF(IF($W$9=0,"",INDEX('DEF_CALL_DECISION_SUPPORT'!$A$1:$U$1496,$W$9,3))<4,"Sample Watch • ","")&IF(B6="All situations","Broad Concept Proxy","D&D + Concept Match • Concept Proxy")) -> MATCHING SCOPE: No Defensive Exact-Play Sample • Sample Watch • Broad Concept Proxy
A22: ="Opponent-only exact-play watch. "&IF(X9="","Confirm the concept in the exact-play section; film review required.","Proxy concept: "&X9&". These metrics are not proof against the named play.") -> Opponent-only exact-play watch. Proxy concept: OUTSIDE ZONE. These metrics are not proof against the named play.
A30: BEST CALLS BY OFFENSIVE CONCEPT
A31: These metrics describe the tagged concept across the imported defensive sample. A candidate remains a signal to confirm on film.
A32: Concept | B32: Concept Call-Fit Candidate | C32: Reps | D32: Defensive Success Rate | E32: Explosive Allowed Rate | F32: Average Gain Allowed | G32: Call Fit Score | H32: Confidence | I32: Call Label | J32: MATCHING SCOPE | K32: Coach Note | L32: Proxy concept / context
A33: 3 STEP | B33: =IF($Z33=0,"Film Review Required",INDEX('DEF_CALL_DECISION_SUPPORT'!$A$1:$U$1496,$Z33,2)) -> REBEL | C33: =IF($Z33=0,"",INDEX('DEF_CALL_DECISION_SUPPORT'!$A$1:$U$1496,$Z33,3)) -> 4 | D33: =IF($Z33=0,"",INDEX('DEF_CALL_DECISION_SUPPORT'!$A$1:$U$1496,$Z33,4)) -> 0.75 | E33: =IF($Z33=0,"",INDEX('DEF_CALL_DECISION_SUPPORT'!$A$1:$U$1496,$Z33,5)) -> 0 | F33: =IF($Z33=0,"",INDEX('DEF_CALL_DECISION_SUPPORT'!$A$1:$U$1496,$Z33,6)) -> 3.75 | G33: =IF($Z33=0,"",INDEX('DEF_CALL_DECISION_SUPPORT'!$A$1:$U$1496,$Z33,10)) -> 78.8 | H33: =IF($Z33=0,"",INDEX('DEF_CALL_DECISION_SUPPORT'!$A$1:$U$1496,$Z33,9)) -> MEDIUM | I33: =IF($Z33=0,"",INDEX('DEF_CALL_DECISION_SUPPORT'!$A$1:$U$1496,$Z33,11)) -> Good Candidate | J33: =IF(Z33=0,"Film Review Required",IF(C33<4,"Sample Watch • ","")&"Broad Concept Proxy") -> Broad Concept Proxy | K33: =IF($Z33=0,"No matching defensive reps; film confirmation needed.",INDEX('DEF_CALL_DECISION_SUPPORT'!$A$1:$U$1496,$Z33,12)) -> Good call-fit signal; confirm on film. | Z33: =IFERROR(MATCH(LEN($A33)&":"&$A33&"|",'DEF_CALL_DECISION_SUPPORT'!$U$1264:$U$1440,0)+1264-1,0) -> 1275
A34: 5 STEP | B34: =IF($Z34=0,"Film Review Required",INDEX('DEF_CALL_DECISION_SUPPORT'!$A$1:$U$1496,$Z34,2)) -> RAMBO | C34: =IF($Z34=0,"",INDEX('DEF_CALL_DECISION_SUPPORT'!$A$1:$U$1496,$Z34,3)) -> 4 | D34: =IF($Z34=0,"",INDEX('DEF_CALL_DECISION_SUPPORT'!$A$1:$U$1496,$Z34,4)) -> 1 | E34: =IF($Z34=0,"",INDEX('DEF_CALL_DECISION_SUPPORT'!$A$1:$U$1496,$Z34,5)) -> 0 | F34: =IF($Z34=0,"",INDEX('DEF_CALL_DECISION_SUPPORT'!$A$1:$U$1496,$Z34,6)) -> 1 | G34: =IF($Z34=0,"",INDEX('DEF_CALL_DECISION_SUPPORT'!$A$1:$U$1496,$Z34,10)) -> 99 | H34: =IF($Z34=0,"",INDEX('DEF_CALL_DECISION_SUPPORT'!$A$1:$U$1496,$Z34,9)) -> MEDIUM | I34: =IF($Z34=0,"",INDEX('DEF_CALL_DECISION_SUPPORT'!$A$1:$U$1496,$Z34,11)) -> Strong Candidate | J34: =IF(Z34=0,"Film Review Required",IF(C34<4,"Sample Watch • ","")&"Broad Concept Proxy") -> Broad Concept Proxy | K34: =IF($Z34=0,"No matching defensive reps; film confirmation needed.",INDEX('DEF_CALL_DECISION_SUPPORT'!$A$1:$U$1496,$Z34,12)) -> Strong call-fit candidate; confirm on film. | Z34: =IFERROR(MATCH(LEN($A34)&":"&$A34&"|",'DEF_CALL_DECISION_SUPPORT'!$U$1264:$U$1440,0)+1264-1,0) -> 1306
A35: BELLY | B35: =IF($Z35=0,"Film Review Required",INDEX('DEF_CALL_DECISION_SUPPORT'!$A$1:$U$1496,$Z35,2)) -> GOLD | C35: =IF($Z35=0,"",INDEX('DEF_CALL_DECISION_SUPPORT'!$A$1:$U$1496,$Z35,3)) -> 1 | D35: =IF($Z35=0,"",INDEX('DEF_CALL_DECISION_SUPPORT'!$A$1:$U$1496,$Z35,4)) -> 0 | E35: =IF($Z35=0,"",INDEX('DEF_CALL_DECISION_SUPPORT'!$A$1:$U$1496,$Z35,5)) -> 0 | F35: =IF($Z35=0,"",INDEX('DEF_CALL_DECISION_SUPPORT'!$A$1:$U$1496,$Z35,6)) -> 1 | G35: =IF($Z35=0,"",INDEX('DEF_CALL_DECISION_SUPPORT'!$A$1:$U$1496,$Z35,10)) -> 29 | H35: =IF($Z35=0,"",INDEX('DEF_CALL_DECISION_SUPPORT'!$A$1:$U$1496,$Z35,9)) -> TRACK | I35: =IF($Z35=0,"",INDEX('DEF_CALL_DECISION_SUPPORT'!$A$1:$U$1496,$Z35,11)) -> Track Only | J35: =IF(Z35=0,"Film Review Required",IF(C35<4,"Sample Watch • ","")&"Broad Concept Proxy") -> Sample Watch • Broad Concept Proxy | K35: =IF($Z35=0,"No matching defensive reps; film confirmation needed.",INDEX('DEF_CALL_DECISION_SUPPORT'!$A$1:$U$1496,$Z35,12)) -> Track only; not enough sample. | Z35: =IFERROR(MATCH(LEN($A35)&":"&$A35&"|",'DEF_CALL_DECISION_SUPPORT'!$U$1264:$U$1440,0)+1264-1,0) -> 1321
A36: BOOT | B36: =IF($Z36=0,"Film Review Required",INDEX('DEF_CALL_DECISION_SUPPORT'!$A$1:$U$1496,$Z36,2)) -> KEY CAPTAIN | C36: =IF($Z36=0,"",INDEX('DEF_CALL_DECISION_SUPPORT'!$A$1:$U$1496,$Z36,3)) -> 1 | D36: =IF($Z36=0,"",INDEX('DEF_CALL_DECISION_SUPPORT'!$A$1:$U$1496,$Z36,4)) -> 1 | E36: =IF($Z36=0,"",INDEX('DEF_CALL_DECISION_SUPPORT'!$A$1:$U$1496,$Z36,5)) -> 0 | F36: =IF($Z36=0,"",INDEX('DEF_CALL_DECISION_SUPPORT'!$A$1:$U$1496,$Z36,6)) -> 0 | G36: =IF($Z36=0,"",INDEX('DEF_CALL_DECISION_SUPPORT'!$A$1:$U$1496,$Z36,10)) -> 100 | H36: =IF($Z36=0,"",INDEX('DEF_CALL_DECISION_SUPPORT'!$A$1:$U$1496,$Z36,9)) -> TRACK | I36: =IF($Z36=0,"",INDEX('DEF_CALL_DECISION_SUPPORT'!$A$1:$U$1496,$Z36,11)) -> Track Only | J36: =IF(Z36=0,"Film Review Required",IF(C36<4,"Sample Watch • ","")&"Broad Concept Proxy") -> Sample Watch • Broad Concept Proxy | K36: =IF($Z36=0,"No matching defensive reps; film confirmation needed.",INDEX('DEF_CALL_DECISION_SUPPORT'!$A$1:$U$1496,$Z36,12)) -> Track only; not enough sample. | Z36: =IFERROR(MATCH(LEN($A36)&":"&$A36&"|",'DEF_CALL_DECISION_SUPPORT'!$U$1264:$U$1440,0)+1264-1,0) -> 1322
A37: COUNTER | B37: =IF($Z37=0,"Film Review Required",INDEX('DEF_CALL_DECISION_SUPPORT'!$A$1:$U$1496,$Z37,2)) -> BOOGIE | C37: =IF($Z37=0,"",INDEX('DEF_CALL_DECISION_SUPPORT'!$A$1:$U$1496,$Z37,3)) -> 2 | D37: =IF($Z37=0,"",INDEX('DEF_CALL_DECISION_SUPPORT'!$A$1:$U$1496,$Z37,4)) -> 0.5 | E37: =IF($Z37=0,"",INDEX('DEF_CALL_DECISION_SUPPORT'!$A$1:$U$1496,$Z37,5)) -> 0 | F37: =IF($Z37=0,"",INDEX('DEF_CALL_DECISION_SUPPORT'!$A$1:$U$1496,$Z37,6)) -> 5 | G37: =IF($Z37=0,"",INDEX('DEF_CALL_DECISION_SUPPORT'!$A$1:$U$1496,$Z37,10)) -> 60 | H37: =IF($Z37=0,"",INDEX('DEF_CALL_DECISION_SUPPORT'!$A$1:$U$1496,$Z37,9)) -> TRACK | I37: =IF($Z37=0,"",INDEX('DEF_CALL_DECISION_SUPPORT'!$A$1:$U$1496,$Z37,11)) -> Track Only | J37: =IF(Z37=0,"Film Review Required",IF(C37<4,"Sample Watch • ","")&"Broad Concept Proxy") -> Sample Watch • Broad Concept Proxy | K37: =IF($Z37=0,"No matching defensive reps; film confirmation needed.",INDEX('DEF_CALL_DECISION_SUPPORT'!$A$1:$U$1496,$Z37,12)) -> Track only; not enough sample. | Z37: =IFERROR(MATCH(LEN($A37)&":"&$A37&"|",'DEF_CALL_DECISION_SUPPORT'!$U$1264:$U$1440,0)+1264-1,0) -> 1325
A38: DASH | B38: =IF($Z38=0,"Film Review Required",INDEX('DEF_CALL_DECISION_SUPPORT'!$A$1:$U$1496,$Z38,2)) -> RAMBO | C38: =IF($Z38=0,"",INDEX('DEF_CALL_DECISION_SUPPORT'!$A$1:$U$1496,$Z38,3)) -> 1 | D38: =IF($Z38=0,"",INDEX('DEF_CALL_DECISION_SUPPORT'!$A$1:$U$1496,$Z38,4)) -> 1 | E38: =IF($Z38=0,"",INDEX('DEF_CALL_DECISION_SUPPORT'!$A$1:$U$1496,$Z38,5)) -> 0 | F38: =IF($Z38=0,"",INDEX('DEF_CALL_DECISION_SUPPORT'!$A$1:$U$1496,$Z38,6)) -> 0 | G38: =IF($Z38=0,"",INDEX('DEF_CALL_DECISION_SUPPORT'!$A$1:$U$1496,$Z38,10)) -> 100 | H38: =IF($Z38=0,"",INDEX('DEF_CALL_DECISION_SUPPORT'!$A$1:$U$1496,$Z38,9)) -> TRACK | I38: =IF($Z38=0,"",INDEX('DEF_CALL_DECISION_SUPPORT'!$A$1:$U$1496,$Z38,11)) -> Track Only | J38: =IF(Z38=0,"Film Review Required",IF(C38<4,"Sample Watch • ","")&"Broad Concept Proxy") -> Sample Watch • Broad Concept Proxy | K38: =IF($Z38=0,"No matching defensive reps; film confirmation needed.",INDEX('DEF_CALL_DECISION_SUPPORT'!$A$1:$U$1496,$Z38,12)) -> Track only; not enough sample. | Z38: =IFERROR(MATCH(LEN($A38)&":"&$A38&"|",'DEF_CALL_DECISION_SUPPORT'!$U$1264:$U$1440,0)+1264-1,0) -> 1337
A39: DRAW | B39: =IF($Z39=0,"Film Review Required",INDEX('DEF_CALL_DECISION_SUPPORT'!$A$1:$U$1496,$Z39,2)) -> BOURBON | C39: =IF($Z39=0,"",INDEX('DEF_CALL_DECISION_SUPPORT'!$A$1:$U$1496,$Z39,3)) -> 1 | D39: =IF($Z39=0,"",INDEX('DEF_CALL_DECISION_SUPPORT'!$A$1:$U$1496,$Z39,4)) -> 0 | E39: =IF($Z39=0,"",INDEX('DEF_CALL_DECISION_SUPPORT'!$A$1:$U$1496,$Z39,5)) -> 1 | F39: =IF($Z39=0,"",INDEX('DEF_CALL_DECISION_SUPPORT'!$A$1:$U$1496,$Z39,6)) -> 14 | G39: =IF($Z39=0,"",INDEX('DEF_CALL_DECISION_SUPPORT'!$A$1:$U$1496,$Z39,10)) -> 0 | H39: =IF($Z39=0,"",INDEX('DEF_CALL_DECISION_SUPPORT'!$A$1:$U$1496,$Z39,9)) -> TRACK | I39: =IF($Z39=0,"",INDEX('DEF_CALL_DECISION_SUPPORT'!$A$1:$U$1496,$Z39,11)) -> Explosive Alert | J39: =IF(Z39=0,"Film Review Required",IF(C39<4,"Sample Watch • ","")&"Broad Concept Proxy") -> Sample Watch • Broad Concept Proxy | K39: =IF($Z39=0,"No matching defensive reps; film confirmation needed.",INDEX('DEF_CALL_DECISION_SUPPORT'!$A$1:$U$1496,$Z39,12)) -> Explosive risk; review clips before using as answer. | Z39: =IFERROR(MATCH(LEN($A39)&":"&$A39&"|",'DEF_CALL_DECISION_SUPPORT'!$U$1264:$U$1440,0)+1264-1,0) -> 1338
A40: DUO | B40: =IF($Z40=0,"Film Review Required",INDEX('DEF_CALL_DECISION_SUPPORT'!$A$1:$U$1496,$Z40,2)) -> SHINE BUC | C40: =IF($Z40=0,"",INDEX('DEF_CALL_DECISION_SUPPORT'!$A$1:$U$1496,$Z40,3)) -> 1 | D40: =IF($Z40=0,"",INDEX('DEF_CALL_DECISION_SUPPORT'!$A$1:$U$1496,$Z40,4)) -> 1 | E40: =IF($Z40=0,"",INDEX('DEF_CALL_DECISION_SUPPORT'!$A$1:$U$1496,$Z40,5)) -> 0 | F40: =IF($Z40=0,"",INDEX('DEF_CALL_DECISION_SUPPORT'!$A$1:$U$1496,$Z40,6)) -> 3 | G40: =IF($Z40=0,"",INDEX('DEF_CALL_DECISION_SUPPORT'!$A$1:$U$1496,$Z40,10)) -> 97 | H40: =IF($Z40=0,"",INDEX('DEF_CALL_DECISION_SUPPORT'!$A$1:$U$1496,$Z40,9)) -> TRACK | I40: =IF($Z40=0,"",INDEX('DEF_CALL_DECISION_SUPPORT'!$A$1:$U$1496,$Z40,11)) -> Track Only | J40: =IF(Z40=0,"Film Review Required",IF(C40<4,"Sample Watch • ","")&"Broad Concept Proxy") -> Sample Watch • Broad Concept Proxy | K40: =IF($Z40=0,"No matching defensive reps; film confirmation needed.",INDEX('DEF_CALL_DECISION_SUPPORT'!$A$1:$U$1496,$Z40,12)) -> Track only; not enough sample. | Z40: =IFERROR(MATCH(LEN($A40)&":"&$A40&"|",'DEF_CALL_DECISION_SUPPORT'!$U$1264:$U$1440,0)+1264-1,0) -> 1339
A41: FLY SWEEP | B41: =IF($Z41=0,"Film Review Required",INDEX('DEF_CALL_DECISION_SUPPORT'!$A$1:$U$1496,$Z41,2)) -> SWAP | C41: =IF($Z41=0,"",INDEX('DEF_CALL_DECISION_SUPPORT'!$A$1:$U$1496,$Z41,3)) -> 1 | D41: =IF($Z41=0,"",INDEX('DEF_CALL_DECISION_SUPPORT'!$A$1:$U$1496,$Z41,4)) -> 1 | E41: =IF($Z41=0,"",INDEX('DEF_CALL_DECISION_SUPPORT'!$A$1:$U$1496,$Z41,5)) -> 0 | F41: =IF($Z41=0,"",INDEX('DEF_CALL_DECISION_SUPPORT'!$A$1:$U$1496,$Z41,6)) -> 3 | G41: =IF($Z41=0,"",INDEX('DEF_CALL_DECISION_SUPPORT'!$A$1:$U$1496,$Z41,10)) -> 97 | H41: =IF($Z41=0,"",INDEX('DEF_CALL_DECISION_SUPPORT'!$A$1:$U$1496,$Z41,9)) -> TRACK | I41: =IF($Z41=0,"",INDEX('DEF_CALL_DECISION_SUPPORT'!$A$1:$U$1496,$Z41,11)) -> Track Only | J41: =IF(Z41=0,"Film Review Required",IF(C41<4,"Sample Watch • ","")&"Broad Concept Proxy") -> Sample Watch • Broad Concept Proxy | K41: =IF($Z41=0,"No matching defensive reps; film confirmation needed.",INDEX('DEF_CALL_DECISION_SUPPORT'!$A$1:$U$1496,$Z41,12)) -> Track only; not enough sample. | Z41: =IFERROR(MATCH(LEN($A41)&":"&$A41&"|",'DEF_CALL_DECISION_SUPPORT'!$U$1264:$U$1440,0)+1264-1,0) -> 1340
A42: FLY TOSS | B42: =IF($Z42=0,"Film Review Required",INDEX('DEF_CALL_DECISION_SUPPORT'!$A$1:$U$1496,$Z42,2)) -> KEY CAPTAIN | C42: =IF($Z42=0,"",INDEX('DEF_CALL_DECISION_SUPPORT'!$A$1:$U$1496,$Z42,3)) -> 1 | D42: =IF($Z42=0,"",INDEX('DEF_CALL_DECISION_SUPPORT'!$A$1:$U$1496,$Z42,4)) -> 1 | E42: =IF($Z42=0,"",INDEX('DEF_CALL_DECISION_SUPPORT'!$A$1:$U$1496,$Z42,5)) -> 0 | F42: =IF($Z42=0,"",INDEX('DEF_CALL_DECISION_SUPPORT'!$A$1:$U$1496,$Z42,6)) -> 2 | G42: =IF($Z42=0,"",INDEX('DEF_CALL_DECISION_SUPPORT'!$A$1:$U$1496,$Z42,10)) -> 98 | H42: =IF($Z42=0,"",INDEX('DEF_CALL_DECISION_SUPPORT'!$A$1:$U$1496,$Z42,9)) -> TRACK | I42: =IF($Z42=0,"",INDEX('DEF_CALL_DECISION_SUPPORT'!$A$1:$U$1496,$Z42,11)) -> Track Only | J42: =IF(Z42=0,"Film Review Required",IF(C42<4,"Sample Watch • ","")&"Broad Concept Proxy") -> Sample Watch • Broad Concept Proxy | K42: =IF($Z42=0,"No matching defensive reps; film confirmation needed.",INDEX('DEF_CALL_DECISION_SUPPORT'!$A$1:$U$1496,$Z42,12)) -> Track only; not enough sample. | Z42: =IFERROR(MATCH(LEN($A42)&":"&$A42&"|",'DEF_CALL_DECISION_SUPPORT'!$U$1264:$U$1440,0)+1264-1,0) -> 1341
A43: FUZZY | B43: =IF($Z43=0,"Film Review Required",INDEX('DEF_CALL_DECISION_SUPPORT'!$A$1:$U$1496,$Z43,2)) -> SMOKE BUC | C43: =IF($Z43=0,"",INDEX('DEF_CALL_DECISION_SUPPORT'!$A$1:$U$1496,$Z43,3)) -> 1 | D43: =IF($Z43=0,"",INDEX('DEF_CALL_DECISION_SUPPORT'!$A$1:$U$1496,$Z43,4)) -> 1 | E43: =IF($Z43=0,"",INDEX('DEF_CALL_DECISION_SUPPORT'!$A$1:$U$1496,$Z43,5)) -> 0 | F43: =IF($Z43=0,"",INDEX('DEF_CALL_DECISION_SUPPORT'!$A$1:$U$1496,$Z43,6)) -> 4 | G43: =IF($Z43=0,"",INDEX('DEF_CALL_DECISION_SUPPORT'!$A$1:$U$1496,$Z43,10)) -> 96 | H43: =IF($Z43=0,"",INDEX('DEF_CALL_DECISION_SUPPORT'!$A$1:$U$1496,$Z43,9)) -> TRACK | I43: =IF($Z43=0,"",INDEX('DEF_CALL_DECISION_SUPPORT'!$A$1:$U$1496,$Z43,11)) -> Track Only | J43: =IF(Z43=0,"Film Review Required",IF(C43<4,"Sample Watch • ","")&"Broad Concept Proxy") -> Sample Watch • Broad Concept Proxy | K43: =IF($Z43=0,"No matching defensive reps; film confirmation needed.",INDEX('DEF_CALL_DECISION_SUPPORT'!$A$1:$U$1496,$Z43,12)) -> Track only; not enough sample. | Z43: =IFERROR(MATCH(LEN($A43)&":"&$A43&"|",'DEF_CALL_DECISION_SUPPORT'!$U$1264:$U$1440,0)+1264-1,0) -> 1344
A44: G | B44: =IF($Z44=0,"Film Review Required",INDEX('DEF_CALL_DECISION_SUPPORT'!$A$1:$U$1496,$Z44,2)) -> Film Review Required | C44: =IF($Z44=0,"",INDEX('DEF_CALL_DECISION_SUPPORT'!$A$1:$U$1496,$Z44,3)) | D44: =IF($Z44=0,"",INDEX('DEF_CALL_DECISION_SUPPORT'!$A$1:$U$1496,$Z44,4)) | E44: =IF($Z44=0,"",INDEX('DEF_CALL_DECISION_SUPPORT'!$A$1:$U$1496,$Z44,5)) | F44: =IF($Z44=0,"",INDEX('DEF_CALL_DECISION_SUPPORT'!$A$1:$U$1496,$Z44,6)) | G44: =IF($Z44=0,"",INDEX('DEF_CALL_DECISION_SUPPORT'!$A$1:$U$1496,$Z44,10)) | H44: =IF($Z44=0,"",INDEX('DEF_CALL_DECISION_SUPPORT'!$A$1:$U$1496,$Z44,9)) | I44: =IF($Z44=0,"",INDEX('DEF_CALL_DECISION_SUPPORT'!$A$1:$U$1496,$Z44,11)) | J44: =IF(Z44=0,"Film Review Required",IF(C44<4,"Sample Watch • ","")&"Broad Concept Proxy") -> Film Review Required | K44: =IF($Z44=0,"No matching defensive reps; film confirmation needed.",INDEX('DEF_CALL_DECISION_SUPPORT'!$A$1:$U$1496,$Z44,12)) -> No matching defensive reps; film confirmation needed. | Z44: =IFERROR(MATCH(LEN($A44)&":"&$A44&"|",'DEF_CALL_DECISION_SUPPORT'!$U$1264:$U$1440,0)+1264-1,0) -> 0
... A59: WHAM | B59: =IF($Z59=0,"Film Review Required",INDEX('DEF_CALL_DECISION_SUPPORT'!$A$1:$U$1496,$Z59,2)) -> Film Review Required | C59: =IF($Z59=0,"",INDEX('DEF_CALL_DECISION_SUPPORT'!$A$1:$U$1496,$Z59,3)) | D59: =IF($Z59=0,"",INDEX('DEF_CALL_DECISION_SUPPORT'!$A$1:$U$1496,$Z59,4)) | E59: =IF($Z59=0,"",INDEX('DEF_CALL_DECISION_SUPPORT'!$A$1:$U$1496,$Z59,5)) | F59: =IF($Z59=0,"",INDEX('DEF_CALL_DECISION_SUPPORT'!$A$1:$U$1496,$Z59,6)) | G59: =IF($Z59=0,"",INDEX('DEF_CALL_DECISION_SUPPORT'!$A$1:$U$1496,$Z59,10)) | H59: =IF($Z59=0,"",INDEX('DEF_CALL_DECISION_SUPPORT'!$A$1:$U$1496,$Z59,9)) | I59: =IF($Z59=0,"",INDEX('DEF_CALL_DECISION_SUPPORT'!$A$1:$U$1496,$Z59,11)) | J59: =IF(Z59=0,"Film Review Required",IF(C59<4,"Sample Watch • ","")&"Broad Concept Proxy") -> Film Review Required | K59: =IF($Z59=0,"No matching defensive reps; film confirmation needed.",INDEX('DEF_CALL_DECISION_SUPPORT'!$A$1:$U$1496,$Z59,12)) -> No matching defensive reps; film confirmation needed. | Z59: =IFERROR(MATCH(LEN($A59)&":"&$A59&"|",'DEF_CALL_DECISION_SUPPORT'!$U$1264:$U$1440,0)+1264-1,0) -> 0
A64: OPPONENT EXACT PLAY WATCH / CONCEPT PROXY
A65: Actual playcalls are opponent film/practice watches. Confirmed concept fields below support proxies only. Blank ambiguous mappings require coach confirmation.
...

Sheet DEF_CALL_DECISION_SUPPORT
A1: DEFENSIVE CALL DECISION SUPPORT
A2: START | C2: FIND A CALL | F2: OPPONENT ALERTS | I2: PRACTICE
A3: Detailed concept and context evidence behind the lookup board. Exact opponent plays are watch items; defensive performance is never claimed as exact-play proof.
A7: 1. D&D + HOT CALL
A8: Rates and scores describe only the stated defensive self-scout context. Small samples remain watch items.
A9: Context | B9: Hot Call | C9: Reps | D9: Defensive Success Rate | E9: Explosive Allowed Rate | F9: Average Gain Allowed | G9: Rush % | H9: Dropback % | I9: Confidence | J9: Call Fit Score | K9: Call Label | L9: Coach Note | M9: Situation | N9: Personnel | O9: Structure | P9: Concept | Q9: Opponent Actual Playcall | R9: Evidence Basis
A10: 1D 1-3 | B10: 9 DICE | C10: =COUNTIFS('DEF_SELF_SCOUT_IMPORT'!$L$42:$L$1040,"Y",'DEF_SELF_SCOUT_IMPORT'!$E$42:$E$1040,SUBSTITUTE(SUBSTITUTE(SUBSTITUTE($B10,"~","~~"),"*","~*"),"?","~?"),'DEF_SELF_SCOUT_IMPORT'!$Q$42:$Q$1040,SUBSTITUTE(SUBSTITUTE(SUBSTITUTE($M10,"~","~~"),"*","~*"),"?","~?")) -> 1 | D10: =IF($C10=0,"",SUMIFS('DEF_SELF_SCOUT_IMPORT'!$J$42:$J$1040,'DEF_SELF_SCOUT_IMPORT'!$L$42:$L$1040,"Y",'DEF_SELF_SCOUT_IMPORT'!$E$42:$E$1040,SUBSTITUTE(SUBSTITUTE(SUBSTITUTE($B10,"~","~~"),"*","~*"),"?","~?"),'DEF_SELF_SCOUT_IMPORT'!$Q$42:$Q$1040,SUBSTITUTE(SUBSTITUTE(SUBSTITUTE($M10,"~","~~"),"*","~*"),"?","~?"))/$C10) -> 0 | E10: =IF($C10=0,"",SUMIFS('DEF_SELF_SCOUT_IMPORT'!$K$42:$K$1040,'DEF_SELF_SCOUT_IMPORT'!$L$42:$L$1040,"Y",'DEF_SELF_SCOUT_IMPORT'!$E$42:$E$1040,SUBSTITUTE(SUBSTITUTE(SUBSTITUTE($B10,"~","~~"),"*","~*"),"?","~?"),'DEF_SELF_SCOUT_IMPORT'!$Q$42:$Q$1040,SUBSTITUTE(SUBSTITUTE(SUBSTITUTE($M10,"~","~~"),"*","~*"),"?","~?"))/$C10) -> 0 | F10: =IF($C10=0,"",AVERAGEIFS('DEF_SELF_SCOUT_IMPORT'!$I$42:$I$1040,'DEF_SELF_SCOUT_IMPORT'!$L$42:$L$1040,"Y",'DEF_SELF_SCOUT_IMPORT'!$E$42:$E$1040,SUBSTITUTE(SUBSTITUTE(SUBSTITUTE($B10,"~","~~"),"*","~*"),"?","~?"),'DEF_SELF_SCOUT_IMPORT'!$Q$42:$Q$1040,SUBSTITUTE(SUBSTITUTE(SUBSTITUTE($M10,"~","~~"),"*","~*"),"?","~?"))) -> 1 | G10: =IF($C10=0,"",COUNTIFS('DEF_SELF_SCOUT_IMPORT'!$L$42:$L$1040,"Y",'DEF_SELF_SCOUT_IMPORT'!$E$42:$E$1040,SUBSTITUTE(SUBSTITUTE(SUBSTITUTE($B10,"~","~~"),"*","~*"),"?","~?"),'DEF_SELF_SCOUT_IMPORT'!$Q$42:$Q$1040,SUBSTITUTE(SUBSTITUTE(SUBSTITUTE($M10,"~","~~"),"*","~*"),"?","~?"),'DEF_SELF_SCOUT_IMPORT'!$H$42:$H$1040,"RUSH")/$C10) -> 0 | H10: =IF($C10=0,"",COUNTIFS('DEF_SELF_SCOUT_IMPORT'!$L$42:$L$1040,"Y",'DEF_SELF_SCOUT_IMPORT'!$E$42:$E$1040,SUBSTITUTE(SUBSTITUTE(SUBSTITUTE($B10,"~","~~"),"*","~*"),"?","~?"),'DEF_SELF_SCOUT_IMPORT'!$Q$42:$Q$1040,SUBSTITUTE(SUBSTITUTE(SUBSTITUTE($M10,"~","~~"),"*","~*"),"?","~?"),'DEF_SELF_SCOUT_IMPORT'!$H$42:$H$1040,"DROPBACK")/$C10) -> 0 | I10: =IF(C10=0,"",IF(C10<=2,"TRACK",IF(C10=3,"LOW",IF(C10<=6,"MEDIUM","HIGH")))) -> TRACK | J10: =IF(C10=0,"",ROUND(D10*70+(1-E10)*20+MAX(0,MIN(1,(10-F10)/10))*10,1)) -> 29 | K10: =IF(C10=0,"No Evidence",IF(C10<=2,IF(E10>0,"Explosive Alert","Track Only"),IF(C10=3,"Sample Watch",IF(E10>=START_HERE!$B$31,"Explosive Alert",IF(J10>=80,"Strong Candidate",IF(J10>=65,"Good Candidate",IF(J10>=50,"Mixed / Review","Problem Call"))))))) -> Track Only | L10: =IF(COUNTIFS('DEF_SELF_SCOUT_IMPORT'!$L$42:$L$1040,"Y",'DEF_SELF_SCOUT_IMPORT'!$E$42:$E$1040,SUBSTITUTE(SUBSTITUTE(SUBSTITUTE($B10,"~","~~"),"*","~*"),"?","~?"),'DEF_SELF_SCOUT_IMPORT'!$Q$42:$Q$1040,SUBSTITUTE(SUBSTITUTE(SUBSTITUTE($M10,"~","~~"),"*","~*"),"?","~?"),'DEF_SELF_SCOUT_IMPORT'!$J$42:$J$1040,"")>0,"Unscored clean outcome; review result tags before using score.",IF(C10=0,"No matching defensive reps; film confirmation needed.",IF(K10="Explosive Alert","Explosive risk; review clips before using as answer.",IF(C10<=2,"Track only; not enough sample.",IF(C10=3,IF(E10>0,"Sample watch with explosive exposure; review clips and build the sample.",IF(J10>=65,"Good signal, but sample is limited.","Sample watch; review clips and build the sample.")),IF(K10="Problem Call","Problem area; practice or call-sheet review.",IF(K10="Strong Candidate","Strong call-fit candidate; confirm on film.",IF(K10="Good Candidate","Good call-fit signal; confirm on film.","Mixed signal; review fit and execution on film.")))))))) -> Track only; not enough sample. | M10: 1D 1-3 | R10: Sample Watch • Defensive context signal | S10: 6:1D 1-3| | T10: =IF(C10=0,0,IF(C10>=CALL_LOOKUP_BOARD!$B$7,IF(OR(K10="Problem Call",K10="Explosive Alert"),10000000,20000000),0)+IF(C10>=CALL_LOOKUP_BOARD!$B$7,J10*1000+MIN(C10,999),C10*1000+J10)+0.00999900) -> 1029.01 | U10: =IF(C10=0,"",IF(COUNTIFS($S$10:$S$178,SUBSTITUTE(SUBSTITUTE(SUBSTITUTE(S10,"~","~~"),"*","~*"),"?","~?"),$T$10:$T$178,">"&T10)=0,S10,""))
A11: 1D 1-3 | B11: GOLD | C11: =COUNTIFS('DEF_SELF_SCOUT_IMPORT'!$L$42:$L$1040,"Y",'DEF_SELF_SCOUT_IMPORT'!$E$42:$E$1040,SUBSTITUTE(SUBSTITUTE(SUBSTITUTE($B11,"~","~~"),"*","~*"),"?","~?"),'DEF_SELF_SCOUT_IMPORT'!$Q$42:$Q$1040,SUBSTITUTE(SUBSTITUTE(SUBSTITUTE($M11,"~","~~"),"*","~*"),"?","~?")) -> 2 | D11: =IF($C11=0,"",SUMIFS('DEF_SELF_SCOUT_IMPORT'!$J$42:$J$1040,'DEF_SELF_SCOUT_IMPORT'!$L$42:$L$1040,"Y",'DEF_SELF_SCOUT_IMPORT'!$E$42:$E$1040,SUBSTITUTE(SUBSTITUTE(SUBSTITUTE($B11,"~","~~"),"*","~*"),"?","~?"),'DEF_SELF_SCOUT_IMPORT'!$Q$42:$Q$1040,SUBSTITUTE(SUBSTITUTE(SUBSTITUTE($M11,"~","~~"),"*","~*"),"?","~?"))/$C11) -> 1 | E11: =IF($C11=0,"",SUMIFS('DEF_SELF_SCOUT_IMPORT'!$K$42:$K$1040,'DEF_SELF_SCOUT_IMPORT'!$L$42:$L$1040,"Y",'DEF_SELF_SCOUT_IMPORT'!$E$42:$E$1040,SUBSTITUTE(SUBSTITUTE(SUBSTITUTE($B11,"~","~~"),"*","~*"),"?","~?"),'DEF_SELF_SCOUT_IMPORT'!$Q$42:$Q$1040,SUBSTITUTE(SUBSTITUTE(SUBSTITUTE($M11,"~","~~"),"*","~*"),"?","~?"))/$C11) -> 0 | F11: =IF($C11=0,"",AVERAGEIFS('DEF_SELF_SCOUT_IMPORT'!$I$42:$I$1040,'DEF_SELF_SCOUT_IMPORT'!$L$42:$L$1040,"Y",'DEF_SELF_SCOUT_IMPORT'!$E$42:$E$1040,SUBSTITUTE(SUBSTITUTE(SUBSTITUTE($B11,"~","~~"),"*","~*"),"?","~?"),'DEF_SELF_SCOUT_IMPORT'!$Q$42:$Q$1040,SUBSTITUTE(SUBSTITUTE(SUBSTITUTE($M11,"~","~~"),"*","~*"),"?","~?"))) -> 1.5 | G11: =IF($C11=0,"",COUNTIFS('DEF_SELF_SCOUT_IMPORT'!$L$42:$L$1040,"Y",'DEF_SELF_SCOUT_IMPORT'!$E$42:$E$1040,SUBSTITUTE(SUBSTITUTE(SUBSTITUTE($B11,"~","~~"),"*","~*"),"?","~?"),'DEF_SELF_SCOUT_IMPORT'!$Q$42:$Q$1040,SUBSTITUTE(SUBSTITUTE(SUBSTITUTE($M11,"~","~~"),"*","~*"),"?","~?"),'DEF_SELF_SCOUT_IMPORT'!$H$42:$H$1040,"RUSH")/$C11) -> 1 | H11: =IF($C11=0,"",COUNTIFS('DEF_SELF_SCOUT_IMPORT'!$L$42:$L$1040,"Y",'DEF_SELF_SCOUT_IMPORT'!$E$42:$E$1040,SUBSTITUTE(SUBSTITUTE(SUBSTITUTE($B11,"~","~~"),"*","~*"),"?","~?"),'DEF_SELF_SCOUT_IMPORT'!$Q$42:$Q$1040,SUBSTITUTE(SUBSTITUTE(SUBSTITUTE($M11,"~","~~"),"*","~*"),"?","~?"),'DEF_SELF_SCOUT_IMPORT'!$H$42:$H$1040,"DROPBACK")/$C11) -> 0 | I11: =IF(C11=0,"",IF(C11<=2,"TRACK",IF(C11=3,"LOW",IF(C11<=6,"MEDIUM","HIGH")))) -> TRACK | J11: =IF(C11=0,"",ROUND(D11*70+(1-E11)*20+MAX(0,MIN(1,(10-F11)/10))*10,1)) -> 98.5 | K11: =IF(C11=0,"No Evidence",IF(C11<=2,IF(E11>0,"Explosive Alert","Track Only"),IF(C11=3,"Sample Watch",IF(E11>=START_HERE!$B$31,"Explosive Alert",IF(J11>=80,"Strong Candidate",IF(J11>=65,"Good Candidate",IF(J11>=50,"Mixed / Review","Problem Call"))))))) -> Track Only | L11: =IF(COUNTIFS('DEF_SELF_SCOUT_IMPORT'!$L$42:$L$1040,"Y",'DEF_SELF_SCOUT_IMPORT'!$E$42:$E$1040,SUBSTITUTE(SUBSTITUTE(SUBSTITUTE($B11,"~","~~"),"*","~*"),"?","~?"),'DEF_SELF_SCOUT_IMPORT'!$Q$42:$Q$1040,SUBSTITUTE(SUBSTITUTE(SUBSTITUTE($M11,"~","~~"),"*","~*"),"?","~?"),'DEF_SELF_SCOUT_IMPORT'!$J$42:$J$1040,"")>0,"Unscored clean outcome; review result tags before using score.",IF(C11=0,"No matching defensive reps; film confirmation needed.",IF(K11="Explosive Alert","Explosive risk; review clips before using as answer.",IF(C11<=2,"Track only; not enough sample.",IF(C11=3,IF(E11>0,"Sample watch with explosive exposure; review clips and build the sample.",IF(J11>=65,"Good signal, but sample is limited.","Sample watch; review clips and build the sample.")),IF(K11="Problem Call","Problem area; practice or call-sheet review.",IF(K11="Strong Candidate","Strong call-fit candidate; confirm on film.",IF(K11="Good Candidate","Good call-fit signal; confirm on film.","Mixed signal; review fit and execution on film.")))))))) -> Track only; not enough sample. | M11: 1D 1-3 | R11: Sample Watch • Defensive context signal | S11: 6:1D 1-3| | T11: =IF(C11=0,0,IF(C11>=CALL_LOOKUP_BOARD!$B$7,IF(OR(K11="Problem Call",K11="Explosive Alert"),10000000,20000000),0)+IF(C11>=CALL_LOOKUP_BOARD!$B$7,J11*1000+MIN(C11,999),C11*1000+J11)+0.00999800) -> 2098.51 | U11: =IF(C11=0,"",IF(COUNTIFS($S$10:$S$178,SUBSTITUTE(SUBSTITUTE(SUBSTITUTE(S11,"~","~~"),"*","~*"),"?","~?"),$T$10:$T$178,">"&T11)=0,S11,"")) -> 6:1D 1-3|
A12: 1D 11+ | B12: BOOGIE | C12: =COUNTIFS('DEF_SELF_SCOUT_IMPORT'!$L$42:$L$1040,"Y",'DEF_SELF_SCOUT_IMPORT'!$E$42:$E$1040,SUBSTITUTE(SUBSTITUTE(SUBSTITUTE($B12,"~","~~"),"*","~*"),"?","~?"),'DEF_SELF_SCOUT_IMPORT'!$Q$42:$Q$1040,SUBSTITUTE(SUBSTITUTE(SUBSTITUTE($M12,"~","~~"),"*","~*"),"?","~?")) -> 1 | D12: =IF($C12=0,"",SUMIFS('DEF_SELF_SCOUT_IMPORT'!$J$42:$J$1040,'DEF_SELF_SCOUT_IMPORT'!$L$42:$L$1040,"Y",'DEF_SELF_SCOUT_IMPORT'!$E$42:$E$1040,SUBSTITUTE(SUBSTITUTE(SUBSTITUTE($B12,"~","~~"),"*","~*"),"?","~?"),'DEF_SELF_SCOUT_IMPORT'!$Q$42:$Q$1040,SUBSTITUTE(SUBSTITUTE(SUBSTITUTE($M12,"~","~~"),"*","~*"),"?","~?"))/$C12) -> 1 | E12: =IF($C12=0,"",SUMIFS('DEF_SELF_SCOUT_IMPORT'!$K$42:$K$1040,'DEF_SELF_SCOUT_IMPORT'!$L$42:$L$1040,"Y",'DEF_SELF_SCOUT_IMPORT'!$E$42:$E$1040,SUBSTITUTE(SUBSTITUTE(SUBSTITUTE($B12,"~","~~"),"*","~*"),"?","~?"),'DEF_SELF_SCOUT_IMPORT'!$Q$42:$Q$1040,SUBSTITUTE(SUBSTITUTE(SUBSTITUTE($M12,"~","~~"),"*","~*"),"?","~?"))/$C12) -> 0 | F12: =IF($C12=0,"",AVERAGEIFS('DEF_SELF_SCOUT_IMPORT'!$I$42:$I$1040,'DEF_SELF_SCOUT_IMPORT'!$L$42:$L$1040,"Y",'DEF_SELF_SCOUT_IMPORT'!$E$42:$E$1040,SUBSTITUTE(SUBSTITUTE(SUBSTITUTE($B12,"~","~~"),"*","~*"),"?","~?"),'DEF_SELF_SCOUT_IMPORT'!$Q$42:$Q$1040,SUBSTITUTE(SUBSTITUTE(SUBSTITUTE($M12,"~","~~"),"*","~*"),"?","~?"))) -> 2 | G12: =IF($C12=0,"",COUNTIFS('DEF_SELF_SCOUT_IMPORT'!$L$42:$L$1040,"Y",'DEF_SELF_SCOUT_IMPORT'!$E$42:$E$1040,SUBSTITUTE(SUBSTITUTE(SUBSTITUTE($B12,"~","~~"),"*","~*"),"?","~?"),'DEF_SELF_SCOUT_IMPORT'!$Q$42:$Q$1040,SUBSTITUTE(SUBSTITUTE(SUBSTITUTE($M12,"~","~~"),"*","~*"),"?","~?"),'DEF_SELF_SCOUT_IMPORT'!$H$42:$H$1040,"RUSH")/$C12) -> 1 | H12: =IF($C12=0,"",COUNTIFS('DEF_SELF_SCOUT_IMPORT'!$L$42:$L$1040,"Y",'DEF_SELF_SCOUT_IMPORT'!$E$42:$E$1040,SUBSTITUTE(SUBSTITUTE(SUBSTITUTE($B12,"~","~~"),"*","~*"),"?","~?"),'DEF_SELF_SCOUT_IMPORT'!$Q$42:$Q$1040,SUBSTITUTE(SUBSTITUTE(SUBSTITUTE($M12,"~","~~"),"*","~*"),"?","~?"),'DEF_SELF_SCOUT_IMPORT'!$H$42:$H$1040,"DROPBACK")/$C12) -> 0 | I12: =IF(C12=0,"",IF(C12<=2,"TRACK",IF(C12=3,"LOW",IF(C12<=6,"MEDIUM","HIGH")))) -> TRACK | J12: =IF(C12=0,"",ROUND(D12*70+(1-E12)*20+MAX(0,MIN(1,(10-F12)/10))*10,1)) -> 98 | K12: =IF(C12=0,"No Evidence",IF(C12<=2,IF(E12>0,"Explosive Alert","Track Only"),IF(C12=3,"Sample Watch",IF(E12>=START_HERE!$B$31,"Explosive Alert",IF(J12>=80,"Strong Candidate",IF(J12>=65,"Good Candidate",IF(J12>=50,"Mixed / Review","Problem Call"))))))) -> Track Only | L12: =IF(COUNTIFS('DEF_SELF_SCOUT_IMPORT'!$L$42:$L$1040,"Y",'DEF_SELF_SCOUT_IMPORT'!$E$42:$E$1040,SUBSTITUTE(SUBSTITUTE(SUBSTITUTE($B12,"~","~~"),"*","~*"),"?","~?"),'DEF_SELF_SCOUT_IMPORT'!$Q$42:$Q$1040,SUBSTITUTE(SUBSTITUTE(SUBSTITUTE($M12,"~","~~"),"*","~*"),"?","~?"),'DEF_SELF_SCOUT_IMPORT'!$J$42:$J$1040,"")>0,"Unscored clean outcome; review result tags before using score.",IF(C12=0,"No matching defensive reps; film confirmation needed.",IF(K12="Explosive Alert","Explosive risk; review clips before using as answer.",IF(C12<=2,"Track only; not enough sample.",IF(C12=3,IF(E12>0,"Sample watch with explosive exposure; review clips and build the sample.",IF(J12>=65,"Good signal, but sample is limited.","Sample watch; review clips and build the sample.")),IF(K12="Problem Call","Problem area; practice or call-sheet review.",IF(K12="Strong Candidate","Strong call-fit candidate; confirm on film.",IF(K12="Good Candidate","Good call-fit signal; confirm on film.","Mixed signal; review fit and execution on film.")))))))) -> Track only; not enough sample. | M12: 1D 11+ | R12: Sample Watch • Defensive context signal | S12: 6:1D 11+| | T12: =IF(C12=0,0,IF(C12>=CALL_LOOKUP_BOARD!$B$7,IF(OR(K12="Problem Call",K12="Explosive Alert"),10000000,20000000),0)+IF(C12>=CALL_LOOKUP_BOARD!$B$7,J12*1000+MIN(C12,999),C12*1000+J12)+0.00999700) -> 1098.01 | U12: =IF(C12=0,"",IF(COUNTIFS($S$10:$S$178,SUBSTITUTE(SUBSTITUTE(SUBSTITUTE(S12,"~","~~"),"*","~*"),"?","~?"),$T$10:$T$178,">"&T12)=0,S12,"")) -> 6:1D 11+|
A13: 1D 11+ | B13: FALCON | C13: =COUNTIFS('DEF_SELF_SCOUT_IMPORT'!$L$42:$L$1040,"Y",'DEF_SELF_SCOUT_IMPORT'!$E$42:$E$1040,SUBSTITUTE(SUBSTITUTE(SUBSTITUTE($B13,"~","~~"),"*","~*"),"?","~?"),'DEF_SELF_SCOUT_IMPORT'!$Q$42:$Q$1040,SUBSTITUTE(SUBSTITUTE(SUBSTITUTE($M13,"~","~~"),"*","~*"),"?","~?")) -> 1 | D13: =IF($C13=0,"",SUMIFS('DEF_SELF_SCOUT_IMPORT'!$J$42:$J$1040,'DEF_SELF_SCOUT_IMPORT'!$L$42:$L$1040,"Y",'DEF_SELF_SCOUT_IMPORT'!$E$42:$E$1040,SUBSTITUTE(SUBSTITUTE(SUBSTITUTE($B13,"~","~~"),"*","~*"),"?","~?"),'DEF_SELF_SCOUT_IMPORT'!$Q$42:$Q$1040,SUBSTITUTE(SUBSTITUTE(SUBSTITUTE($M13,"~","~~"),"*","~*"),"?","~?"))/$C13) -> 1 | E13: =IF($C13=0,"",SUMIFS('DEF_SELF_SCOUT_IMPORT'!$K$42:$K$1040,'DEF_SELF_SCOUT_IMPORT'!$L$42:$L$1040,"Y",'DEF_SELF_SCOUT_IMPORT'!$E$42:$E$1040,SUBSTITUTE(SUBSTITUTE(SUBSTITUTE($B13,"~","~~"),"*","~*"),"?","~?"),'DEF_SELF_SCOUT_IMPORT'!$Q$42:$Q$1040,SUBSTITUTE(SUBSTITUTE(SUBSTITUTE($M13,"~","~~"),"*","~*"),"?","~?"))/$C13) -> 0 | F13: =IF($C13=0,"",AVERAGEIFS('DEF_SELF_SCOUT_IMPORT'!$I$42:$I$1040,'DEF_SELF_SCOUT_IMPORT'!$L$42:$L$1040,"Y",'DEF_SELF_SCOUT_IMPORT'!$E$42:$E$1040,SUBSTITUTE(SUBSTITUTE(SUBSTITUTE($B13,"~","~~"),"*","~*"),"?","~?"),'DEF_SELF_SCOUT_IMPORT'!$Q$42:$Q$1040,SUBSTITUTE(SUBSTITUTE(SUBSTITUTE($M13,"~","~~"),"*","~*"),"?","~?"))) -> 3 | G13: =IF($C13=0,"",COUNTIFS('DEF_SELF_SCOUT_IMPORT'!$L$42:$L$1040,"Y",'DEF_SELF_SCOUT_IMPORT'!$E$42:$E$1040,SUBSTITUTE(SUBSTITUTE(SUBSTITUTE($B13,"~","~~"),"*","~*"),"?","~?"),'DEF_SELF_SCOUT_IMPORT'!$Q$42:$Q$1040,SUBSTITUTE(SUBSTITUTE(SUBSTITUTE($M13,"~","~~"),"*","~*"),"?","~?"),'DEF_SELF_SCOUT_IMPORT'!$H$42:$H$1040,"RUSH")/$C13) -> 1 | H13: =IF($C13=0,"",COUNTIFS('DEF_SELF_SCOUT_IMPORT'!$L$42:$L$1040,"Y",'DEF_SELF_SCOUT_IMPORT'!$E$42:$E$1040,SUBSTITUTE(SUBSTITUTE(SUBSTITUTE($B13,"~","~~"),"*","~*"),"?","~?"),'DEF_SELF_SCOUT_IMPORT'!$Q$42:$Q$1040,SUBSTITUTE(SUBSTITUTE(SUBSTITUTE($M13,"~","~~"),"*","~*"),"?","~?"),'DEF_SELF_SCOUT_IMPORT'!$H$42:$H$1040,"DROPBACK")/$C13) -> 0 | I13: =IF(C13=0,"",IF(C13<=2,"TRACK",IF(C13=3,"LOW",IF(C13<=6,"MEDIUM","HIGH")))) -> TRACK | J13: =IF(C13=0,"",ROUND(D13*70+(1-E13)*20+MAX(0,MIN(1,(10-F13)/10))*10,1)) -> 97 | K13: =IF(C13=0,"No Evidence",IF(C13<=2,IF(E13>0,"Explosive Alert","Track Only"),IF(C13=3,"Sample Watch",IF(E13>=START_HERE!$B$31,"Explosive Alert",IF(J13>=80,"Strong Candidate",IF(J13>=65,"Good Candidate",IF(J13>=50,"Mixed / Review","Problem Call"))))))) -> Track Only | L13: =IF(COUNTIFS('DEF_SELF_SCOUT_IMPORT'!$L$42:$L$1040,"Y",'DEF_SELF_SCOUT_IMPORT'!$E$42:$E$1040,SUBSTITUTE(SUBSTITUTE(SUBSTITUTE($B13,"~","~~"),"*","~*"),"?","~?"),'DEF_SELF_SCOUT_IMPORT'!$Q$42:$Q$1040,SUBSTITUTE(SUBSTITUTE(SUBSTITUTE($M13,"~","~~"),"*","~*"),"?","~?"),'DEF_SELF_SCOUT_IMPORT'!$J$42:$J$1040,"")>0,"Unscored clean outcome; review result tags before using score.",IF(C13=0,"No matching defensive reps; film confirmation needed.",IF(K13="Explosive Alert","Explosive risk; review clips before using as answer.",IF(C13<=2,"Track only; not enough sample.",IF(C13=3,IF(E13>0,"Sample watch with explosive exposure; review clips and build the sample.",IF(J13>=65,"Good signal, but sample is limited.","Sample watch; review clips and build the sample.")),IF(K13="Problem Call","Problem area; practice or call-sheet review.",IF(K13="Strong Candidate","Strong call-fit candidate; confirm on film.",IF(K13="Good Candidate","Good call-fit signal; confirm on film.","Mixed signal; review fit and execution on film.")))))))) -> Track only; not enough sample. | M13: 1D 11+ | R13: Sample Watch • Defensive context signal | S13: 6:1D 11+| | T13: =IF(C13=0,0,IF(C13>=CALL_LOOKUP_BOARD!$B$7,IF(OR(K13="Problem Call",K13="Explosive Alert"),10000000,20000000),0)+IF(C13>=CALL_LOOKUP_BOARD!$B$7,J13*1000+MIN(C13,999),C13*1000+J13)+0.00999600) -> 1097.01 | U13: =IF(C13=0,"",IF(COUNTIFS($S$10:$S$178,SUBSTITUTE(SUBSTITUTE(SUBSTITUTE(S13,"~","~~"),"*","~*"),"?","~?"),$T$10:$T$178,">"&T13)=0,S13,""))
